<?xml version="1.0" ?>
<!-- =================================================================================== -->
<!-- |    This document was autogenerated by xacro from a0509.urdf.xacro               | -->
<!-- |    EDITING THIS FILE BY HAND IS NOT RECOMMENDED                                 | -->
<!-- =================================================================================== -->
<robot name="a0509">
  <material name="black">
    <color rgba="0.0 0.0 0.0 1.0"/>
  </material>
  <material name="white">
    <color rgba="1.0 1.0 1.0 1.0"/>
  </material>
  <material name="orange">
    <color rgba="1.0 0.4 0.0 1.0"/>
  </material>
  <material name="dr_gray">
    <color rgba="0.490 0.490 0.486 1.0"/>
  </material>
  <material name="dr_white">
    <color rgba="0.941 0.941 0.941 1.0"/>
  </material>
  <link name="base_link">
    <inertial>
      <mass value="2.198"/>
      <origin xyz="-1e-06   -0.001096    0.058957"/>
      <inertia ixx="0.010511" ixy="4.9786e-06" ixz="7.1839e-06" iyy="0.012033" iyz="-2.3529e-05" izz="0.012481"/>
    </inertial>
    <collision>
      <origin rpy="0 0 0" xyz="0 0 0"/>
      <geometry>
        <mesh filename="package://dsr_description2/meshes/a0509_collision/A0509_0_0.dae" scale="0.001 0.001 0.001"/>
      </geometry>
    </collision>
    <visual>
      <origin rpy="0 0 0" xyz="0 0 0"/>
      <geometry>
        <mesh filename="package://dsr_description2/meshes/a0509_white/A0509_0_0.dae" scale="0.001 0.001 0.001"/>
      </geometry>
    </visual>
  </link>
  <!-- joint 1 -->
  <joint name="joint_1" type="revolute">
    <parent link="base_link"/>
    <child link="link_1"/>
    <origin rpy="0 0 0" xyz="0 0 0.1555"/>
    <axis xyz="0 0 1"/>
    <limit effort="194" lower="-6.2832" upper="6.2832" velocity="3.1416"/>
    <dynamics friction="0"/>
  </joint>
  <link name="link_1">
    <inertial>
      <mass value="3.715"/>
      <origin xyz="-6.9e-05    0.024423   -0.007375"/>
      <inertia ixx="0.01899" ixy="7.8574e-07" ixz="1.865e-05" iyy="0.013731" iyz="-0.00072828" izz="0.01686"/>
    </inertial>
    <collision>
      <origin rpy="0 0 0" xyz="0 0 0"/>
      <geometry>
        <mesh filename="package://dsr_description2/meshes/a0509_collision/A0509_1_0.dae" scale="0.001 0.001 0.001"/>
      </geometry>
    </collision>
    <visual>
      <origin rpy="0 0 0" xyz="0 0 0"/>
      <geometry>
        <mesh filename="package://dsr_description2/meshes/a0509_white/A0509_1_0.dae" scale="0.001 0.001 0.001"/>
      </geometry>
    </visual>
    <collision>
      <origin rpy="0 0 0" xyz="0 0 0"/>
      <geometry>
        <mesh filename="package://dsr_description2/meshes/a0509_collision/A0509_1_1.dae" scale="0.001 0.001 0.001"/>
      </geometry>
    </collision>
    <visual>
      <origin rpy="0 0 0" xyz="0 0 0"/>
      <geometry>
        <mesh filename="package://dsr_description2/meshes/a0509_white/A0509_1_1.dae" scale="0.001 0.001 0.001"/>
      </geometry>
    </visual>
    <collision>
      <origin rpy="0 0 0" xyz="0 0 0"/>
      <geometry>
        <mesh filename="package://dsr_description2/meshes/a0509_collision/A0509_1_2.dae" scale="0.001 0.001 0.001"/>
      </geometry>
    </collision>
    <visual>
      <origin rpy="0 0 0" xyz="0 0 0"/>
      <geometry>
        <mesh filename="package://dsr_description2/meshes/a0509_white/A0509_1_2.dae" scale="0.001 0.001 0.001"/>
      </geometry>
    </visual>
  </link>
  <!-- joint2 -->
  <joint name="joint_2" type="revolute">
    <parent link="link_1"/>
    <child link="link_2"/>
    <origin rpy="0 -1.571 -1.571" xyz="0 0 0"/>
    <axis xyz="0 0 1"/>
    <limit effort="194" lower="-6.2832" upper="6.2832" velocity="3.1416"/>
    <dynamics friction="0"/>
  </joint>
  <link name="link_2">
    <inertial>
      <mass value="6.837"/>
      <origin xyz="0.20449 -1.2521e-17     0.13271"/>
      <inertia ixx="0.019399" ixy="0.00010317" ixz="4.2985e-06" iyy="0.25627" iyz="5.1674e-06" izz="0.25442"/>
    </inertial>
    <collision>
      <origin rpy="0 0 0" xyz="0 0 0"/>
      <geometry>
        <mesh filename="package://dsr_description2/meshes/a0509_collision/A0509_2_0.dae" scale="0.001 0.001 0.001"/>
      </geometry>
    </collision>
    <visual>
      <origin rpy="0 0 0" xyz="0 0 0"/>
      <geometry>
        <mesh filename="package://dsr_description2/meshes/a0509_white/A0509_2_0.dae" scale="0.001 0.001 0.001"/>
      </geometry>
    </visual>
    <collision>
      <origin rpy="0 0 0" xyz="0 0 0"/>
      <geometry>
        <mesh filename="package://dsr_description2/meshes/a0509_collision/A0509_2_1.dae" scale="0.001 0.001 0.001"/>
      </geometry>
    </collision>
    <visual>
      <origin rpy="0 0 0" xyz="0 0 0"/>
      <geometry>
        <mesh filename="package://dsr_description2/meshes/a0509_white/A0509_2_1.dae" scale="0.001 0.001 0.001"/>
      </geometry>
    </visual>
    <collision>
      <origin rpy="0 0 0" xyz="0 0 0"/>
      <geometry>
        <mesh filename="package://dsr_description2/meshes/a0509_collision/A0509_2_2.dae" scale="0.001 0.001 0.001"/>
      </geometry>
    </collision>
    <visual>
      <origin rpy="0 0 0" xyz="0 0 0"/>
      <geometry>
        <mesh filename="package://dsr_description2/meshes/a0509_white/A0509_2_2.dae" scale="0.001 0.001 0.001"/>
      </geometry>
    </visual>
  </link>
  <!-- joint3 -->
  <joint name="joint_3" type="revolute">
    <parent link="link_2"/>
    <child link="link_3"/>
    <origin rpy="0 0 1.571" xyz="0.409 0 0"/>
    <axis xyz="0 0 1"/>
    <limit effort="163" lower="-2.7925" upper="2.7925" velocity="3.1416"/>
    <dynamics friction="0"/>
  </joint>
  <link name="link_3">
    <inertial>
      <mass value="2.769"/>
      <origin xyz="7.1e-05   -0.005123    0.033009"/>
      <inertia ixx="0.012526" ixy="-7.1869e-06" ixz="1.3345e-05" iyy="0.013868" iyz="-0.00047287" izz="0.0088186"/>
    </inertial>
    <collision>
      <origin rpy="0 0 0" xyz="0 0 0"/>
      <geometry>
        <mesh filename="package://dsr_description2/meshes/a0509_collision/A0509_3_0.dae" scale="0.001 0.001 0.001"/>
      </geometry>
    </collision>
    <visual>
      <origin rpy="0 0 0" xyz="0 0 0"/>
      <geometry>
        <mesh filename="package://dsr_description2/meshes/a0509_white/A0509_3_0.dae" scale="0.001 0.001 0.001"/>
      </geometry>
    </visual>
    <collision>
      <origin rpy="0 0 0" xyz="0 0 0"/>
      <geometry>
        <mesh filename="package://dsr_description2/meshes/a0509_collision/A0509_3_1.dae" scale="0.001 0.001 0.001"/>
      </geometry>
    </collision>
    <visual>
      <origin rpy="0 0 0" xyz="0 0 0"/>
      <geometry>
        <mesh filename="package://dsr_description2/meshes/a0509_white/A0509_3_1.dae" scale="0.001 0.001 0.001"/>
      </geometry>
    </visual>
  </link>
  <!-- joint4 -->
  <joint name="joint_4" type="revolute">
    <parent link="link_3"/>
    <child link="link_4"/>
    <origin rpy="1.571 0 0" xyz="0 -0.367 0"/>
    <axis xyz="0 0 1"/>
    <limit effort="50" lower="-6.2832" upper="6.2832" velocity="6.2832"/>
    <dynamics friction="0"/>
  </joint>
  <link name="link_4">
    <inertial>
      <mass value="2.679"/>
      <origin xyz="-8.6e-05    0.086348   -0.086031"/>
      <inertia ixx="0.056068" ixy="2.2109e-05" ixz="1.4522e-05" iyy="0.047122" iyz="-0.014997" izz="0.013329"/>
    </inertial>
    <collision>
      <origin rpy="0 0 0" xyz="0 0 0"/>
      <geometry>
        <mesh filename="package://dsr_description2/meshes/a0509_collision/A0509_4_0.dae" scale="0.001 0.001 0.001"/>
      </geometry>
    </collision>
    <visual>
      <origin rpy="0 0 0" xyz="0 0 0"/>
      <geometry>
        <mesh filename="package://dsr_description2/meshes/a0509_white/A0509_4_0.dae" scale="0.001 0.001 0.001"/>
      </geometry>
    </visual>
    <collision>
      <origin rpy="0 0 0" xyz="0 0 0"/>
      <geometry>
        <mesh filename="package://dsr_description2/meshes/a0509_collision/A0509_4_1.dae" scale="0.001 0.001 0.001"/>
      </geometry>
    </collision>
    <visual>
      <origin rpy="0 0 0" xyz="0 0 0"/>
      <geometry>
        <mesh filename="package://dsr_description2/meshes/a0509_white/A0509_4_1.dae" scale="0.001 0.001 0.001"/>
      </geometry>
    </visual>
  </link>
  <!-- joint5 -->
  <joint name="joint_5" type="revolute">
    <parent link="link_4"/>
    <child link="link_5"/>
    <origin rpy="-1.571 0 0" xyz="0 0 0"/>
    <axis xyz="0 0 1"/>
    <limit effort="50" lower="-6.2832" upper="6.2832" velocity="6.2832"/>
    <dynamics friction="0"/>
  </joint>
  <link name="link_5">
    <inertial>
      <mass value="2.051"/>
      <origin xyz="9.1e-05   -0.006457    0.015434"/>
      <inertia ixx="0.0090788" ixy="-5.3997e-06" ixz="8.3955e-06" iyy="0.0084721" iyz="-0.0001816" izz="0.010453"/>
    </inertial>
    <collision>
      <origin rpy="0 0 0" xyz="0 0 0"/>
      <geometry>
        <mesh filename="package://dsr_description2/meshes/a0509_collision/A0509_5_0.dae" scale="0.001 0.001 0.001"/>
      </geometry>
    </collision>
    <visual>
      <origin rpy="0 0 0" xyz="0 0 0"/>
      <geometry>
        <mesh filename="package://dsr_description2/meshes/a0509_white/A0509_5_0.dae" scale="0.001 0.001 0.001"/>
      </geometry>
    </visual>
    <collision>
      <origin rpy="0 0 0" xyz="0 0 0"/>
      <geometry>
        <mesh filename="package://dsr_description2/meshes/a0509_collision/A0509_5_1.dae" scale="0.001 0.001 0.001"/>
      </geometry>
    </collision>
    <visual>
      <origin rpy="0 0 0" xyz="0 0 0"/>
      <geometry>
        <mesh filename="package://dsr_description2/meshes/a0509_white/A0509_5_1.dae" scale="0.001 0.001 0.001"/>
      </geometry>
    </visual>
  </link>
  <!-- joint6 -->
  <joint name="joint_6" type="revolute">
    <parent link="link_5"/>
    <child link="link_6"/>
    <origin rpy="1.571 0 0" xyz="0 -0.124 0"/>
    <axis xyz="0 0 1"/>
    <limit effort="50" lower="-6.2832" upper="6.2832" velocity="6.2832"/>
    <dynamics friction="0"/>
  </joint>
  <link name="link_6">
    <inertial>
      <mass value="0.773"/>
      <origin xyz="-2.2e-05      -7e-06   -0.051746"/>
      <inertia ixx="0.0087483" ixy="7.9428e-06" ixz="1.7034e-06" iyy="0.0078566" iyz="9.6857e-06" izz="0.0044452"/>
    </inertial>
    <collision>
      <origin rpy="0 0 0" xyz="0 0 0"/>
      <geometry>
        <mesh filename="package://dsr_description2/meshes/a0509_collision/A0509_6_0.dae" scale="0.001 0.001 0.001"/>
      </geometry>
    </collision>
    <visual>
      <origin rpy="0 0 0" xyz="0 0 0"/>
      <geometry>
        <mesh filename="package://dsr_description2/meshes/a0509_white/A0509_6_0.dae" scale="0.001 0.001 0.001"/>
      </geometry>
    </visual>
  </link>
  <!-- Transmission 1 -->
  <transmission name="tran1">
    <type>transmission_interface/SimpleTransmission</type>
    <joint name="joint1">
      <hardwareInterface>hardware_interface/PositionJointInterface</hardwareInterface>
    </joint>
    <actuator name="motor1">
      <hardwareInterface>hardware_interface/PositionJointInterface</hardwareInterface>
      <mechanicalReduction>1</mechanicalReduction>
    </actuator>
  </transmission>
  <!-- Transmission 2 -->
  <transmission name="tran2">
    <type>transmission_interface/SimpleTransmission</type>
    <joint name="joint2">
      <hardwareInterface>hardware_interface/PositionJointInterface</hardwareInterface>
    </joint>
    <actuator name="motor2">
      <hardwareInterface>hardware_interface/PositionJointInterface</hardwareInterface>
      <mechanicalReduction>1</mechanicalReduction>
    </actuator>
  </transmission>
  <!-- Transmission 3 -->
  <transmission name="tran3">
    <type>transmission_interface/SimpleTransmission</type>
    <joint name="joint3">
      <hardwareInterface>hardware_interface/PositionJointInterface</hardwareInterface>
    </joint>
    <actuator name="motor3">
      <hardwareInterface>hardware_interface/PositionJointInterface</hardwareInterface>
      <mechanicalReduction>1</mechanicalReduction>
    </actuator>
  </transmission>
  <!-- Transmission 4 -->
  <transmission name="tran4">
    <type>transmission_interface/SimpleTransmission</type>
    <joint name="joint4">
      <hardwareInterface>hardware_interface/PositionJointInterface</hardwareInterface>
    </joint>
    <actuator name="motor4">
      <hardwareInterface>hardware_interface/PositionJointInterface</hardwareInterface>
      <mechanicalReduction>1</mechanicalReduction>
    </actuator>
  </transmission>
  <!-- Transmission 5 -->
  <transmission name="tran5">
    <type>transmission_interface/SimpleTransmission</type>
    <joint name="joint5">
      <hardwareInterface>hardware_interface/PositionJointInterface</hardwareInterface>
    </joint>
    <actuator name="motor5">
      <hardwareInterface>hardware_interface/PositionJointInterface</hardwareInterface>
      <mechanicalReduction>1</mechanicalReduction>
    </actuator>
  </transmission>
  <!-- Transmission 6 -->
  <transmission name="tran6">
    <type>transmission_interface/SimpleTransmission</type>
    <joint name="joint6">
      <hardwareInterface>hardware_interface/PositionJointInterface</hardwareInterface>
    </joint>
    <actuator name="motor6">
      <hardwareInterface>hardware_interface/PositionJointInterface</hardwareInterface>
      <mechanicalReduction>1</mechanicalReduction>
    </actuator>
  </transmission>
  <!-- ros_control plugin -->
  <gazebo>
    <plugin filename="ign_ros2_control-system" name="ign_ros2_control::IgnitionROS2ControlPlugin">
      <ros>
        <namespace></namespace>
      </ros>
      <parameters>/home/hardware_team/ros2_ws/install/dsr_controller2/share/dsr_controller2/config/dsr_controller2_gz.yaml</parameters>
      <!-- <controller_manager_name>asd</controller_manager_name> -->
    </plugin>
  </gazebo>
  <!-- Base -->
  <gazebo reference="base_0">
    <kp>100000.0</kp>
    <kd>100.0</kd>
    <mu1>30.0</mu1>
    <mu2>30.0</mu2>
    <maxVel>1.0</maxVel>
    <minDepth>0.001</minDepth>
  </gazebo>
  <!-- Link1 -->
  <gazebo reference="link1">
    <kp>100000.0</kp>
    <kd>100.0</kd>
    <mu1>30.0</mu1>
    <mu2>30.0</mu2>
    <maxVel>1.0</maxVel>
    <minDepth>0.001</minDepth>
  </gazebo>
  <!-- Link2 -->
  <gazebo reference="link2">
    <kp>100000.0</kp>
    <kd>100.0</kd>
    <mu1>30.0</mu1>
    <mu2>30.0</mu2>
    <maxVel>1.0</maxVel>
    <minDepth>0.001</minDepth>
  </gazebo>
  <!-- Link3 -->
  <gazebo reference="link3">
    <kp>100000.0</kp>
    <kd>100.0</kd>
    <mu1>30.0</mu1>
    <mu2>30.0</mu2>
    <maxVel>1.0</maxVel>
    <minDepth>0.001</minDepth>
  </gazebo>
  <!-- Link4 -->
  <gazebo reference="link4">
    <kp>100000.0</kp>
    <kd>100.0</kd>
    <mu1>30.0</mu1>
    <mu2>30.0</mu2>
    <maxVel>1.0</maxVel>
    <minDepth>0.001</minDepth>
  </gazebo>
  <!-- Link5 -->
  <gazebo reference="link5">
    <kp>100000.0</kp>
    <kd>100.0</kd>
    <mu1>30.0</mu1>
    <mu2>30.0</mu2>
    <maxVel>1.0</maxVel>
    <minDepth>0.001</minDepth>
  </gazebo>
  <!-- Link6 -->
  <gazebo reference="link6">
    <kp>100000.0</kp>
    <kd>100.0</kd>
    <mu1>30.0</mu1>
    <mu2>30.0</mu2>
    <maxVel>1.0</maxVel>
    <minDepth>0.001</minDepth>
  </gazebo>
  <link name="world"/>
  <!-- World fixed joint-->
  <joint name="world_fixed" type="fixed">
    <origin rpy="0 0 0" xyz="0 0 0"/>
    <parent link="world"/>
    <child link="base_link"/>
  </joint>
  <ros2_control name="a0509" type="system">
    <hardware>
      <plugin>dsr_hardware2/DRHWInterface</plugin>
      <param name="name">a0509</param>
      <param name="rate">100</param>
      <param name="standby">ture</param>
      <param name="command">none</param>
      <param name="host">0.0.0.0</param>
      <param name="port">12345</param>
      <param name="mode">real</param>
      <param name="model">a0509</param>
      <param name="gripper">none</param>
      <param name="mobile">none</param>
    </hardware>
    <joint name="joint_1">
      <command_interface name="position">
        <param name="min">{-2*pi}</param>
        <param name="max">{2*pi}</param>
      </command_interface>
      <command_interface name="velocity">
        <param name="min">-3.15</param>
        <param name="max">3.15</param>
      </command_interface>
      <state_interface name="position">
        <param name="initial_value">0.0</param>
      </state_interface>
      <state_interface name="velocity"/>
    </joint>
    <joint name="joint_2">
      <command_interface name="position">
        <param name="min">{-2*pi}</param>
        <param name="max">{2*pi}</param>
      </command_interface>
      <command_interface name="velocity">
        <param name="min">-3.15</param>
        <param name="max">3.15</param>
      </command_interface>
      <state_interface name="position">
        <param name="initial_value">0.0</param>
      </state_interface>
      <state_interface name="velocity"/>
    </joint>
    <joint name="joint_3">
      <command_interface name="position">
        <param name="min">{-pi}</param>
        <param name="max">{pi}</param>
      </command_interface>
      <command_interface name="velocity">
        <param name="min">-3.15</param>
        <param name="max">3.15</param>
      </command_interface>
      <state_interface name="position">
        <param name="initial_value">0.0</param>
      </state_interface>
      <state_interface name="velocity"/>
    </joint>
    <joint name="joint_4">
      <command_interface name="position">
        <param name="min">{-2*pi}</param>
        <param name="max">{2*pi}</param>
      </command_interface>
      <command_interface name="velocity">
        <param name="min">-3.2</param>
        <param name="max">3.2</param>
      </command_interface>
      <state_interface name="position">
        <param name="initial_value">0.0</param>
      </state_interface>
      <state_interface name="velocity"/>
    </joint>
    <joint name="joint_5">
      <command_interface name="position">
        <param name="min">{-2*pi}</param>
        <param name="max">{2*pi}</param>
      </command_interface>
      <command_interface name="velocity">
        <param name="min">-3.2</param>
        <param name="max">3.2</param>
      </command_interface>
      <state_interface name="position">
        <param name="initial_value">0.0</param>
      </state_interface>
      <state_interface name="velocity"/>
    </joint>
    <joint name="joint_6">
      <command_interface name="position">
        <param name="min">{-2*pi}</param>
        <param name="max">{2*pi}</param>
      </command_interface>
      <command_interface name="velocity">
        <param name="min">-3.2</param>
        <param name="max">3.2</param>
      </command_interface>
      <state_interface name="position">
        <param name="initial_value">0.0</param>
      </state_interface>
      <state_interface name="velocity"/>
    </joint>
  </ros2_control>
</robot>